<sdf version='1.6'>
  <world name='default'>
    <light name='sun' type='directional'>
      <cast_shadows>1</cast_shadows>
      <pose frame=''>0 0 10 0 -0 0</pose>
      <diffuse>0.8 0.8 0.8 1</diffuse>
      <specular>0.2 0.2 0.2 1</specular>
      <attenuation>
        <range>1000</range>
        <constant>0.9</constant>
        <linear>0.01</linear>
        <quadratic>0.001</quadratic>
      </attenuation>
      <direction>-0.5 0.1 -0.9</direction>
    </light>
    <model name='ground_plane'>
      <static>1</static>
      <link name='link'>
        <collision name='collision'>
          <geometry>
            <plane>
              <normal>0 0 1</normal>
              <size>100 100</size>
            </plane>
          </geometry>
          <surface>
            <friction>
              <ode>
                <mu>100</mu>
                <mu2>50</mu2>
              </ode>
              <torsional>
                <ode/>
              </torsional>
            </friction>
            <contact>
              <ode/>
            </contact>
            <bounce/>
          </surface>
          <max_contacts>10</max_contacts>
        </collision>
        <visual name='visual'>
          <cast_shadows>0</cast_shadows>
          <geometry>
            <plane>
              <normal>0 0 1</normal>
              <size>100 100</size>
            </plane>
          </geometry>
          <material>
            <script>
              <uri>file://media/materials/scripts/gazebo.material</uri>
              <name>Gazebo/Grey</name>
            </script>
          </material>
        </visual>
        <self_collide>0</self_collide>
        <kinematic>0</kinematic>
      </link>
    </model>
    <gravity>0 0 -9.8</gravity>
    <magnetic_field>6e-06 2.3e-05 -4.2e-05</magnetic_field>
    <atmosphere type='adiabatic'/>
    <physics name='default_physics' default='0' type='ode'>
      <max_step_size>0.001</max_step_size>
      <real_time_factor>1</real_time_factor>
      <real_time_update_rate>1000</real_time_update_rate>
    </physics>
    <scene>
      <ambient>0.4 0.4 0.4 1</ambient>
      <background>0.7 0.7 0.7 1</background>
      <shadows>1</shadows>
    </scene>
    <spherical_coordinates>
      <surface_model>EARTH_WGS84</surface_model>
      <latitude_deg>0</latitude_deg>
      <longitude_deg>0</longitude_deg>
      <elevation>0</elevation>
      <heading_deg>0</heading_deg>
    </spherical_coordinates>
    <model name='robot'>
      <link name='base_link'>
        <pose frame=''>0 0 1 0 -0 0</pose>
        <inertial>
          <pose frame=''>0 0 0 0 -0 0</pose>
          <mass>4</mass>
          <inertia>
            <ixx>0.00443333</ixx>
            <ixy>0</ixy>
            <ixz>0</ixz>
            <iyy>0.00443333</iyy>
            <iyz>0</iyz>
            <izz>0.0072</izz>
          </inertia>
        </inertial>
        <collision name='base_link_collision'>
          <pose frame=''>0 0 0 0 -0 0</pose>
          <geometry>
            <mesh>
              <scale>1 1 1</scale>
              <uri>/home/biba/catkin_ws/src/universal_robot/ur_description/meshes/ur5/collision/base.stl</uri>
            </mesh>
          </geometry>
          <max_contacts>10</max_contacts>
          <surface>
            <contact>
              <ode/>
            </contact>
            <bounce/>
            <friction>
              <torsional>
                <ode/>
              </torsional>
              <ode/>
            </friction>
          </surface>
        </collision>
        <visual name='base_link_visual'>
          <pose frame=''>0 0 0 0 -0 0</pose>
          <geometry>
            <mesh>
              <scale>1 1 1</scale>
              <uri>/home/biba/catkin_ws/src/universal_robot/ur_description/meshes/ur5/visual/base.dae</uri>
            </mesh>
          </geometry>
        </visual>
        <self_collide>0</self_collide>
        <kinematic>0</kinematic>
      </link>
      <joint name='world_joint' type='revolute'>
        <child>base_link</child>
        <parent>world</parent>
        <axis>
          <limit>
            <lower>0</lower>
            <upper>0</upper>
          </limit>
          <dynamics>
            <damping>0</damping>
            <friction>0</friction>
            <spring_reference>0</spring_reference>
            <spring_stiffness>0</spring_stiffness>
          </dynamics>
          <use_parent_model_frame>1</use_parent_model_frame>
          <xyz>0 0 1</xyz>
        </axis>
      </joint>
      <link name='shoulder_link'>
        <pose frame=''>0 0 1.08916 0 -0 0</pose>
        <inertial>
          <pose frame=''>0 0 0 0 -0 0</pose>
          <mass>3.7</mass>
          <inertia>
            <ixx>0.0102675</ixx>
            <ixy>0</ixy>
            <ixz>0</ixz>
            <iyy>0.0102675</iyy>
            <iyz>0</iyz>
            <izz>0.00666</izz>
          </inertia>
        </inertial>
        <collision name='shoulder_link_collision'>
          <pose frame=''>0 0 0 0 -0 0</pose>
          <geometry>
            <mesh>
              <scale>1 1 1</scale>
              <uri>/home/biba/catkin_ws/src/universal_robot/ur_description/meshes/ur5/collision/shoulder.stl</uri>
            </mesh>
          </geometry>
          <max_contacts>10</max_contacts>
          <surface>
            <contact>
              <ode/>
            </contact>
            <bounce/>
            <friction>
              <torsional>
                <ode/>
              </torsional>
              <ode/>
            </friction>
          </surface>
        </collision>
        <visual name='shoulder_link_visual'>
          <pose frame=''>0 0 0 0 -0 0</pose>
          <geometry>
            <mesh>
              <scale>1 1 1</scale>
              <uri>/home/biba/catkin_ws/src/universal_robot/ur_description/meshes/ur5/visual/shoulder.dae</uri>
            </mesh>
          </geometry>
        </visual>
        <self_collide>0</self_collide>
        <kinematic>0</kinematic>
      </link>
      <joint name='shoulder_pan_joint' type='revolute'>
        <child>shoulder_link</child>
        <parent>base_link</parent>
        <axis>
          <xyz>0 0 1</xyz>
          <limit>
            <lower>-6.28319</lower>
            <upper>6.28319</upper>
            <effort>150</effort>
            <velocity>3.15</velocity>
          </limit>
          <dynamics>
            <damping>0</damping>
            <friction>0</friction>
            <spring_reference>0</spring_reference>
            <spring_stiffness>0</spring_stiffness>
          </dynamics>
          <use_parent_model_frame>1</use_parent_model_frame>
        </axis>
      </joint>
      <link name='upper_arm_link'>
        <pose frame=''>0 0.13585 1.08916 3.14159 1.57079 3.14159</pose>
        <inertial>
          <pose frame=''>0 0 0.28 0 -0 0</pose>
          <mass>8.393</mass>
          <inertia>
            <ixx>0.226891</ixx>
            <ixy>0</ixy>
            <ixz>0</ixz>
            <iyy>0.226891</iyy>
            <iyz>0</iyz>
            <izz>0.0151074</izz>
          </inertia>
        </inertial>
        <collision name='upper_arm_link_collision'>
          <pose frame=''>0 0 0 0 -0 0</pose>
          <geometry>
            <mesh>
              <scale>1 1 1</scale>
              <uri>/home/biba/catkin_ws/src/universal_robot/ur_description/meshes/ur5/collision/upperarm.stl</uri>
            </mesh>
          </geometry>
          <max_contacts>10</max_contacts>
          <surface>
            <contact>
              <ode/>
            </contact>
            <bounce/>
            <friction>
              <torsional>
                <ode/>
              </torsional>
              <ode/>
            </friction>
          </surface>
        </collision>
        <visual name='upper_arm_link_visual'>
          <pose frame=''>0 0 0 0 -0 0</pose>
          <geometry>
            <mesh>
              <scale>1 1 1</scale>
              <uri>/home/biba/catkin_ws/src/universal_robot/ur_description/meshes/ur5/visual/upperarm.dae</uri>
            </mesh>
          </geometry>
        </visual>
        <self_collide>0</self_collide>
        <kinematic>0</kinematic>
      </link>
      <joint name='shoulder_lift_joint' type='revolute'>
        <child>upper_arm_link</child>
        <parent>shoulder_link</parent>
        <axis>
          <xyz>0 1 0</xyz>
          <limit>
            <lower>-6.28319</lower>
            <upper>6.28319</upper>
            <effort>150</effort>
            <velocity>3.15</velocity>
          </limit>
          <dynamics>
            <damping>0</damping>
            <friction>0</friction>
            <spring_reference>0</spring_reference>
            <spring_stiffness>0</spring_stiffness>
          </dynamics>
          <use_parent_model_frame>1</use_parent_model_frame>
        </axis>
      </joint>
      <link name='forearm_link'>
        <pose frame=''>0.425 0.01615 1.08916 3.14159 1.57079 3.14159</pose>
        <inertial>
          <pose frame=''>0 0 0.25 0 -0 0</pose>
          <mass>2.275</mass>
          <inertia>
            <ixx>0.0494433</ixx>
            <ixy>0</ixy>
            <ixz>0</ixz>
            <iyy>0.0494433</iyy>
            <iyz>0</iyz>
            <izz>0.004095</izz>
          </inertia>
        </inertial>
        <collision name='forearm_link_collision'>
          <pose frame=''>0 0 0 0 -0 0</pose>
          <geometry>
            <mesh>
              <scale>1 1 1</scale>
              <uri>/home/biba/catkin_ws/src/universal_robot/ur_description/meshes/ur5/collision/forearm.stl</uri>
            </mesh>
          </geometry>
          <max_contacts>10</max_contacts>
          <surface>
            <contact>
              <ode/>
            </contact>
            <bounce/>
            <friction>
              <torsional>
                <ode/>
              </torsional>
              <ode/>
            </friction>
          </surface>
        </collision>
        <visual name='forearm_link_visual'>
          <pose frame=''>0 0 0 0 -0 0</pose>
          <geometry>
            <mesh>
              <scale>1 1 1</scale>
              <uri>/home/biba/catkin_ws/src/universal_robot/ur_description/meshes/ur5/visual/forearm.dae</uri>
            </mesh>
          </geometry>
        </visual>
        <self_collide>0</self_collide>
        <kinematic>0</kinematic>
      </link>
      <joint name='elbow_joint' type='revolute'>
        <child>forearm_link</child>
        <parent>upper_arm_link</parent>
        <axis>
          <xyz>0 1 0</xyz>
          <limit>
            <lower>-6.28319</lower>
            <upper>6.28319</upper>
            <effort>150</effort>
            <velocity>3.15</velocity>
          </limit>
          <dynamics>
            <damping>0</damping>
            <friction>0</friction>
            <spring_reference>0</spring_reference>
            <spring_stiffness>0</spring_stiffness>
          </dynamics>
          <use_parent_model_frame>1</use_parent_model_frame>
        </axis>
      </joint>
      <link name='wrist_1_link'>
        <pose frame=''>0.81725 0.01615 1.08916 3.14159 -0 3.14159</pose>
        <inertial>
          <pose frame=''>0 0 0 0 -0 0</pose>
          <mass>1.219</mass>
          <inertia>
            <ixx>0.111173</ixx>
            <ixy>0</ixy>
            <ixz>0</ixz>
            <iyy>0.111173</iyy>
            <iyz>0</iyz>
            <izz>0.21942</izz>
          </inertia>
        </inertial>
        <collision name='wrist_1_link_collision'>
          <pose frame=''>0 0 0 0 -0 0</pose>
          <geometry>
            <mesh>
              <scale>1 1 1</scale>
              <uri>/home/biba/catkin_ws/src/universal_robot/ur_description/meshes/ur5/collision/wrist1.stl</uri>
            </mesh>
          </geometry>
          <max_contacts>10</max_contacts>
          <surface>
            <contact>
              <ode/>
            </contact>
            <bounce/>
            <friction>
              <torsional>
                <ode/>
              </torsional>
              <ode/>
            </friction>
          </surface>
        </collision>
        <visual name='wrist_1_link_visual'>
          <pose frame=''>0 0 0 0 -0 0</pose>
          <geometry>
            <mesh>
              <scale>1 1 1</scale>
              <uri>/home/biba/catkin_ws/src/universal_robot/ur_description/meshes/ur5/visual/wrist1.dae</uri>
            </mesh>
          </geometry>
        </visual>
        <self_collide>0</self_collide>
        <kinematic>0</kinematic>
      </link>
      <joint name='wrist_1_joint' type='revolute'>
        <child>wrist_1_link</child>
        <parent>forearm_link</parent>
        <axis>
          <xyz>0 1 0</xyz>
          <limit>
            <lower>-6.28319</lower>
            <upper>6.28319</upper>
            <effort>28</effort>
            <velocity>3.2</velocity>
          </limit>
          <dynamics>
            <damping>0</damping>
            <friction>0</friction>
            <spring_reference>0</spring_reference>
            <spring_stiffness>0</spring_stiffness>
          </dynamics>
          <use_parent_model_frame>1</use_parent_model_frame>
        </axis>
      </joint>
      <link name='wrist_2_link'>
        <pose frame=''>0.81725 0.10915 1.08916 3.14159 -0 3.14159</pose>
        <inertial>
          <pose frame=''>0 0 0 0 -0 0</pose>
          <mass>1.219</mass>
          <inertia>
            <ixx>0.111173</ixx>
            <ixy>0</ixy>
            <ixz>0</ixz>
            <iyy>0.111173</iyy>
            <iyz>0</iyz>
            <izz>0.21942</izz>
          </inertia>
        </inertial>
        <collision name='wrist_2_link_collision'>
          <pose frame=''>0 0 0 0 -0 0</pose>
          <geometry>
            <mesh>
              <scale>1 1 1</scale>
              <uri>/home/biba/catkin_ws/src/universal_robot/ur_description/meshes/ur5/collision/wrist2.stl</uri>
            </mesh>
          </geometry>
          <max_contacts>10</max_contacts>
          <surface>
            <contact>
              <ode/>
            </contact>
            <bounce/>
            <friction>
              <torsional>
                <ode/>
              </torsional>
              <ode/>
            </friction>
          </surface>
        </collision>
        <visual name='wrist_2_link_visual'>
          <pose frame=''>0 0 0 0 -0 0</pose>
          <geometry>
            <mesh>
              <scale>1 1 1</scale>
              <uri>/home/biba/catkin_ws/src/universal_robot/ur_description/meshes/ur5/visual/wrist2.dae</uri>
            </mesh>
          </geometry>
        </visual>
        <self_collide>0</self_collide>
        <kinematic>0</kinematic>
      </link>
      <joint name='wrist_2_joint' type='revolute'>
        <child>wrist_2_link</child>
        <parent>wrist_1_link</parent>
        <axis>
          <xyz>0 0 -1</xyz>
          <limit>
            <lower>-6.28319</lower>
            <upper>6.28319</upper>
            <effort>28</effort>
            <velocity>3.2</velocity>
          </limit>
          <dynamics>
            <damping>0</damping>
            <friction>0</friction>
            <spring_reference>0</spring_reference>
            <spring_stiffness>0</spring_stiffness>
          </dynamics>
          <use_parent_model_frame>1</use_parent_model_frame>
        </axis>
      </joint>
      <link name='wrist_3_link'>
        <pose frame=''>0.81725 0.10915 0.994509 3.14159 -0 3.14159</pose>
        <inertial>
          <pose frame=''>0 0 0 0 -0 0</pose>
          <mass>0.1879</mass>
          <inertia>
            <ixx>0.0171365</ixx>
            <ixy>0</ixy>
            <ixz>0</ixz>
            <iyy>0.0171365</iyy>
            <iyz>0</iyz>
            <izz>0.033822</izz>
          </inertia>
        </inertial>
        <collision name='wrist_3_link_collision'>
          <pose frame=''>0 0 0 0 -0 0</pose>
          <geometry>
            <mesh>
              <scale>1 1 1</scale>
              <uri>/home/biba/catkin_ws/src/universal_robot/ur_description/meshes/ur5/collision/wrist3.stl</uri>
            </mesh>
          </geometry>
          <max_contacts>10</max_contacts>
          <surface>
            <contact>
              <ode/>
            </contact>
            <bounce/>
            <friction>
              <torsional>
                <ode/>
              </torsional>
              <ode/>
            </friction>
          </surface>
        </collision>
        <collision name='wrist_3_link_fixed_joint_lump__ee_link_collision_1'>
          <pose frame=''>-0 0.0723 0 0 -0 1.5708</pose>
          <geometry>
            <box>
              <size>0.01 0.01 0.01</size>
            </box>
          </geometry>
          <max_contacts>10</max_contacts>
          <surface>
            <contact>
              <ode/>
            </contact>
            <bounce/>
            <friction>
              <torsional>
                <ode/>
              </torsional>
              <ode/>
            </friction>
          </surface>
        </collision>
        <collision name='wrist_3_link_fixed_joint_lump__gripper_body_collision_2'>
          <pose frame=''>-3.8e-05 0.1496 3.8e-05 -1.57 -0 0.000796</pose>
          <geometry>
            <box>
              <size>0.044 0.088 0.16</size>
            </box>
          </geometry>
          <max_contacts>10</max_contacts>
          <surface>
            <contact>
              <ode/>
            </contact>
            <bounce/>
            <friction>
              <torsional>
                <ode/>
              </torsional>
              <ode/>
            </friction>
          </surface>
        </collision>
        <collision name='wrist_3_link_fixed_joint_lump__tcp_frame_collision_3'>
          <pose frame=''>-0.000104 0.232317 -0.021897 -1.57 -0 0.000796</pose>
          <geometry>
            <sphere>
              <radius>0.005</radius>
            </sphere>
          </geometry>
          <max_contacts>10</max_contacts>
          <surface>
            <contact>
              <ode/>
            </contact>
            <bounce/>
            <friction>
              <torsional>
                <ode/>
              </torsional>
              <ode/>
            </friction>
          </surface>
        </collision>
        <collision name='wrist_3_link_fixed_joint_lump__tool_interface_plate_collision_4'>
          <pose frame=''>0 0.08865 0 0 1.57 1.5708</pose>
          <geometry>
            <box>
              <size>0.09525 0.09525 0.0127</size>
            </box>
          </geometry>
          <max_contacts>10</max_contacts>
          <surface>
            <contact>
              <ode/>
            </contact>
            <bounce/>
            <friction>
              <torsional>
                <ode/>
              </torsional>
              <ode/>
            </friction>
          </surface>
        </collision>
        <visual name='wrist_3_link_visual'>
          <pose frame=''>0 0 0 0 -0 0</pose>
          <geometry>
            <mesh>
              <scale>1 1 1</scale>
              <uri>/home/biba/catkin_ws/src/universal_robot/ur_description/meshes/ur5/visual/wrist3.dae</uri>
            </mesh>
          </geometry>
        </visual>
        <visual name='wrist_3_link_fixed_joint_lump__gripper_body_visual_1'>
          <pose frame=''>1e-06 0.1016 -1e-06 -1.57 -0 0.000796</pose>
          <geometry>
            <mesh>
              <scale>1 1 1</scale>
              <uri>/home/biba/catkin_ws/src/Perception-Driven_Manipulation/solution_ws/src/robot_config/meshes/vacuum_gripper_single_suction_cup.STL</uri>
            </mesh>
          </geometry>
        </visual>
        <visual name='wrist_3_link_fixed_joint_lump__tcp_frame_visual_2'>
          <pose frame=''>-0.000104 0.232317 -0.021897 -1.57 -0 0.000796</pose>
          <geometry>
            <sphere>
              <radius>0.005</radius>
            </sphere>
          </geometry>
        </visual>
        <visual name='wrist_3_link_fixed_joint_lump__tool_interface_plate_visual_3'>
          <pose frame=''>0 0.08865 0 0 1.57 1.5708</pose>
          <geometry>
            <box>
              <size>0.09525 0.09525 0.0127</size>
            </box>
          </geometry>
        </visual>
        <self_collide>0</self_collide>
        <kinematic>0</kinematic>
      </link>
      <joint name='wrist_3_joint' type='revolute'>
        <child>wrist_3_link</child>
        <parent>wrist_2_link</parent>
        <axis>
          <xyz>0 1 0</xyz>
          <limit>
            <lower>-6.28319</lower>
            <upper>6.28319</upper>
            <effort>28</effort>
            <velocity>3.2</velocity>
          </limit>
          <dynamics>
            <damping>0</damping>
            <friction>0</friction>
            <spring_reference>0</spring_reference>
            <spring_stiffness>0</spring_stiffness>
          </dynamics>
          <use_parent_model_frame>1</use_parent_model_frame>
        </axis>
      </joint>
      <static>0</static>
      <plugin name='ros_control' filename='libgazebo_ros_control.so'>
        <robotNamespace>/</robotNamespace>
      </plugin>
      <pose frame=''>0 0 0.1 0 -0 0</pose>
    </model>
    <model name='table'>
      <static>1</static>
      <link name='link'>
        <collision name='surface'>
          <pose frame=''>0 0 1 0 -0 0</pose>
          <geometry>
            <box>
              <size>1.5 0.8 0.03</size>
            </box>
          </geometry>
          <surface>
            <friction>
              <ode>
                <mu>0.6</mu>
                <mu2>0.6</mu2>
              </ode>
              <torsional>
                <ode/>
              </torsional>
            </friction>
            <contact>
              <ode/>
            </contact>
            <bounce/>
          </surface>
          <max_contacts>10</max_contacts>
        </collision>
        <visual name='visual1'>
          <pose frame=''>0 0 1 0 -0 0</pose>
          <geometry>
            <box>
              <size>1.5 0.8 0.03</size>
            </box>
          </geometry>
          <material>
            <script>
              <uri>file://media/materials/scripts/gazebo.material</uri>
              <name>Gazebo/Wood</name>
            </script>
          </material>
        </visual>
        <collision name='front_left_leg'>
          <pose frame=''>0.68 0.38 0.5 0 -0 0</pose>
          <geometry>
            <cylinder>
              <radius>0.02</radius>
              <length>1</length>
            </cylinder>
          </geometry>
          <max_contacts>10</max_contacts>
          <surface>
            <contact>
              <ode/>
            </contact>
            <bounce/>
            <friction>
              <torsional>
                <ode/>
              </torsional>
              <ode/>
            </friction>
          </surface>
        </collision>
        <visual name='front_left_leg'>
          <pose frame=''>0.68 0.38 0.5 0 -0 0</pose>
          <geometry>
            <cylinder>
              <radius>0.02</radius>
              <length>1</length>
            </cylinder>
          </geometry>
          <material>
            <script>
              <uri>file://media/materials/scripts/gazebo.material</uri>
              <name>Gazebo/Grey</name>
            </script>
          </material>
        </visual>
        <collision name='front_right_leg'>
          <pose frame=''>0.68 -0.38 0.5 0 -0 0</pose>
          <geometry>
            <cylinder>
              <radius>0.02</radius>
              <length>1</length>
            </cylinder>
          </geometry>
          <max_contacts>10</max_contacts>
          <surface>
            <contact>
              <ode/>
            </contact>
            <bounce/>
            <friction>
              <torsional>
                <ode/>
              </torsional>
              <ode/>
            </friction>
          </surface>
        </collision>
        <visual name='front_right_leg'>
          <pose frame=''>0.68 -0.38 0.5 0 -0 0</pose>
          <geometry>
            <cylinder>
              <radius>0.02</radius>
              <length>1</length>
            </cylinder>
          </geometry>
          <material>
            <script>
              <uri>file://media/materials/scripts/gazebo.material</uri>
              <name>Gazebo/Grey</name>
            </script>
          </material>
        </visual>
        <collision name='back_right_leg'>
          <pose frame=''>-0.68 -0.38 0.5 0 -0 0</pose>
          <geometry>
            <cylinder>
              <radius>0.02</radius>
              <length>1</length>
            </cylinder>
          </geometry>
          <max_contacts>10</max_contacts>
          <surface>
            <contact>
              <ode/>
            </contact>
            <bounce/>
            <friction>
              <torsional>
                <ode/>
              </torsional>
              <ode/>
            </friction>
          </surface>
        </collision>
        <visual name='back_right_leg'>
          <pose frame=''>-0.68 -0.38 0.5 0 -0 0</pose>
          <geometry>
            <cylinder>
              <radius>0.02</radius>
              <length>1</length>
            </cylinder>
          </geometry>
          <material>
            <script>
              <uri>file://media/materials/scripts/gazebo.material</uri>
              <name>Gazebo/Grey</name>
            </script>
          </material>
        </visual>
        <collision name='back_left_leg'>
          <pose frame=''>-0.68 0.38 0.5 0 -0 0</pose>
          <geometry>
            <cylinder>
              <radius>0.02</radius>
              <length>1</length>
            </cylinder>
          </geometry>
          <max_contacts>10</max_contacts>
          <surface>
            <contact>
              <ode/>
            </contact>
            <bounce/>
            <friction>
              <torsional>
                <ode/>
              </torsional>
              <ode/>
            </friction>
          </surface>
        </collision>
        <visual name='back_left_leg'>
          <pose frame=''>-0.68 0.38 0.5 0 -0 0</pose>
          <geometry>
            <cylinder>
              <radius>0.02</radius>
              <length>1</length>
            </cylinder>
          </geometry>
          <material>
            <script>
              <uri>file://media/materials/scripts/gazebo.material</uri>
              <name>Gazebo/Grey</name>
            </script>
          </material>
        </visual>
        <self_collide>0</self_collide>
        <kinematic>0</kinematic>
      </link>
      <pose frame=''>1.05476 0.032738 0 0 -0 0</pose>
    </model>
    <model name='base'>
      <static>1</static>
      <link name='link'>
        <inertial>
          <pose frame=''>0 0 0.035 0 -0 0</pose>
          <mass>0.2</mass>
          <inertia>
            <ixx>1</ixx>
            <ixy>0</ixy>
            <ixz>0</ixz>
            <iyy>1</iyy>
            <iyz>0</iyz>
            <izz>1</izz>
          </inertia>
        </inertial>
        <collision name='collision'>
          <geometry>
            <mesh>
              <uri>model://base/meshes/base.dae</uri>
            </mesh>
          </geometry>
          <max_contacts>10</max_contacts>
          <surface>
            <contact>
              <ode/>
            </contact>
            <bounce/>
            <friction>
              <torsional>
                <ode/>
              </torsional>
              <ode/>
            </friction>
          </surface>
        </collision>
        <visual name='visual'>
          <geometry>
            <mesh>
              <uri>model://base/meshes/base.dae</uri>
            </mesh>
          </geometry>
        </visual>
        <self_collide>0</self_collide>
        <kinematic>0</kinematic>
      </link>
      <pose frame=''>1.19414 0.217254 0 0 -0 0</pose>
    </model>
    <model name='lid'>
      <static>1</static>
      <link name='link'>
        <inertial>
          <pose frame=''>0 0 0.035 0 -0 0</pose>
          <mass>0.2</mass>
          <inertia>
            <ixx>1</ixx>
            <ixy>0</ixy>
            <ixz>0</ixz>
            <iyy>1</iyy>
            <iyz>0</iyz>
            <izz>1</izz>
          </inertia>
        </inertial>
        <collision name='collision'>
          <geometry>
            <mesh>
              <uri>model://lid/meshes/lid.dae</uri>
            </mesh>
          </geometry>
          <max_contacts>10</max_contacts>
          <surface>
            <contact>
              <ode/>
            </contact>
            <bounce/>
            <friction>
              <torsional>
                <ode/>
              </torsional>
              <ode/>
            </friction>
          </surface>
        </collision>
        <visual name='visual'>
          <geometry>
            <mesh>
              <uri>model://lid/meshes/lid.dae</uri>
            </mesh>
          </geometry>
        </visual>
        <self_collide>0</self_collide>
        <kinematic>0</kinematic>
      </link>
      <pose frame=''>1.03156 0.242546 0 0 -0 0</pose>
    </model>
    <state world_name='default'>
      <sim_time>649 935000000</sim_time>
      <real_time>652 289584657</real_time>
      <wall_time>1502203080 254959530</wall_time>
      <iterations>649935</iterations>
      <model name='base'>
        <pose frame=''>0.635586 0.397537 1.01464 0 -0 0</pose>
        <scale>1 1 1</scale>
        <link name='link'>
          <pose frame=''>0.635586 0.397537 1.01464 0 -0 0</pose>
          <velocity>0 0 0 0 -0 0</velocity>
          <acceleration>0 0 0 0 -0 0</acceleration>
          <wrench>0 0 0 0 -0 0</wrench>
        </link>
      </model>
      <model name='ground_plane'>
        <pose frame=''>0 0 0 0 -0 0</pose>
        <scale>1 1 1</scale>
        <link name='link'>
          <pose frame=''>0 0 0 0 -0 0</pose>
          <velocity>0 0 0 0 -0 0</velocity>
          <acceleration>0 0 0 0 -0 0</acceleration>
          <wrench>0 0 0 0 -0 0</wrench>
        </link>
      </model>
      <model name='lid'>
        <pose frame=''>0.677231 0.319684 1.01494 0 -0 0</pose>
        <scale>1 1 1</scale>
        <link name='link'>
          <pose frame=''>0.677231 0.319684 1.01494 0 -0 0</pose>
          <velocity>0 0 0 0 -0 0</velocity>
          <acceleration>0 0 0 0 -0 0</acceleration>
          <wrench>0 0 0 0 -0 0</wrench>
        </link>
      </model>
      <model name='robot'>
        <pose frame=''>3.9e-05 1.4e-05 0.1 1.4e-05 -3.9e-05 5e-06</pose>
        <scale>1 1 1</scale>
        <link name='base_link'>
          <pose frame=''>0 0 1.1 1.4e-05 -3.9e-05 5e-06</pose>
          <velocity>-7e-06 3e-06 -1e-06 -0.000112 -4.8e-05 0.009751</velocity>
          <acceleration>-0.014526 0.005427 -0.001168 -0.223385 -0.095718 0.652977</acceleration>
          <wrench>-0.058103 0.021707 -0.00467 0 -0 0</wrench>
        </link>
        <link name='forearm_link'>
          <pose frame=''>0.424975 0.016624 1.18755 -3.12959 1.56699 -3.12847</pose>
          <velocity>-0.000407 -2e-05 -0.004728 0.000314 0.011353 0.000402</velocity>
          <acceleration>-0.41814 0.080987 -7.56595 -2.35609 -1.20925 0.019568</acceleration>
          <wrench>-0.951269 0.184245 -17.2125 0 -0 0</wrench>
        </link>
        <link name='shoulder_link'>
          <pose frame=''>-3e-06 -2e-06 1.18916 -2.5e-05 7.4e-05 0.001122</pose>
          <velocity>0.000179 -5.8e-05 1e-06 0.000525 0.000931 0.006545</velocity>
          <acceleration>0.179241 -0.058416 0.000736 0.524989 0.931485 0.261952</acceleration>
          <wrench>0.663193 -0.216138 0.002722 0 -0 0</wrench>
        </link>
        <link name='upper_arm_link'>
          <pose frame=''>-0.000156 0.135848 1.18915 -3.12837 1.56701 -3.12725</pose>
          <velocity>-0.000445 -0.000105 9.9e-05 0.000431 0.011313 0.00039</velocity>
          <acceleration>-0.456792 0.004682 -3.06855 0.359559 -1.24664 0.002419</acceleration>
          <wrench>-3.83386 0.039299 -25.7543 0 -0 0</wrench>
        </link>
        <link name='wrist_1_link'>
          <pose frame=''>0.817222 0.017063 1.18606 -3.14152 -0.003935 -3.14048</pose>
          <velocity>-0.000413 0.000122 -0.009175 2e-05 0.011631 0.00025</velocity>
          <acceleration>-0.413319 0.122215 -9.17479 0.01879 -0.935643 0.249159</acceleration>
          <wrench>-0.503836 0.14898 -11.1841 0 -0 0</wrench>
        </link>
        <link name='wrist_2_link'>
          <pose frame=''>0.817118 0.110063 1.18605 -3.14152 -0.003935 -3.14047</pose>
          <velocity>-0.000422 0.00011 -0.009168 1.1e-05 0.011625 0.000239</velocity>
          <acceleration>-0.42167 0.110428 -9.16775 0.009638 -0.941574 0.238141</acceleration>
          <wrench>-0.514016 0.134612 -11.1755 0 -0 0</wrench>
        </link>
        <link name='wrist_3_link'>
          <pose frame=''>0.816745 0.110056 1.0914 -3.14152 -0.003944 -3.14047</pose>
          <velocity>-0.001513 0.000104 -0.009161 3e-06 0.011644 0.000229</velocity>
          <acceleration>-1.51349 0.104288 -9.16129 0.002204 -0.922447 0.228859</acceleration>
          <wrench>-0.284385 0.019596 -1.72141 0 -0 0</wrench>
        </link>
      </model>
      <model name='table'>
        <pose frame=''>0.743734 0.13092 0 0 0 -1.54851</pose>
        <scale>1 1 1</scale>
        <link name='link'>
          <pose frame=''>0.743734 0.13092 0 0 0 -1.54851</pose>
          <velocity>0 0 0 0 -0 0</velocity>
          <acceleration>0 0 0 0 -0 0</acceleration>
          <wrench>0 0 0 0 -0 0</wrench>
        </link>
      </model>
      <light name='sun'>
        <pose frame=''>0 0 10 0 -0 0</pose>
      </light>
    </state>
    <gui fullscreen='0'>
      <camera name='user_camera'>
        <pose frame=''>2.83721 -1.44658 1.46389 0 0.275643 2.35619</pose>
        <view_controller>orbit</view_controller>
        <projection_type>perspective</projection_type>
      </camera>
    </gui>
  </world>
</sdf>
