<?xml version="1.0"?>
<robot name="ur5" xmlns:xacro="http://ros.org/wiki/xacro">

  <xacro:include filename="$(find ur_description)/urdf/ur.transmission.xacro" />
  <xacro:include filename="$(find ur_description)/urdf/ur.gazebo.xacro" />
  <xacro:include filename="$(find robot_config)/urdf/vacuum_gripper_macro.xacro"/>
 <!-- <xacro:include filename="$(find robot_config)/urdf/kinect_sensor_macro.xacro"/> -->
<xacro:include filename="$(find mastering_ros_robot_description_pkg)/urdf/sensors/xtion_pro_live.urdf.xacro"/>
  <!-- Inertia parameters -->
  <property name="base_mass" value="4.0" />  <!-- This mass might be incorrect -->
  <property name="shoulder_mass" value="3.7000" />
  <property name="upper_arm_mass" value="8.3930" />
  <property name="forearm_mass" value="2.2750" />
  <property name="wrist_1_mass" value="1.2190" />
  <property name="wrist_2_mass" value="1.2190" />
  <property name="wrist_3_mass" value="0.1879" />

  <property name="shoulder_cog" value="0.0 0.00193 -0.02561" />
  <property name="upper_arm_cog" value="0.0 -0.024201 0.2125" />
  <property name="forearm_cog" value="0.0 0.0265 0.11993" />
  <property name="wrist_1_cog" value="0.0 0.110949 0.01634" />
  <property name="wrist_2_cog" value="0.0 0.0018 0.11099" />
  <property name="wrist_3_cog" value="0.0 0.001159 0.0" />

 <property name="deg_to_rad" value="0.01745329251994329577"/>
  <!-- Kinematic model -->
  <!-- Properties from urcontrol.conf -->
  <!--
    DH for UR5:
    a = [0.00000, -0.42500, -0.39225,  0.00000,  0.00000,  0.0000]
    d = [0.089159,  0.00000,  0.00000,  0.10915,  0.09465,  0.0823]
    alpha = [ 1.570796327, 0, 0, 1.570796327, -1.570796327, 0 ]
    q_home_offset = [0, -1.570796327, 0, -1.570796327, 0, 0]
    joint_direction = [-1, -1, 1, 1, 1, 1]
    mass = [3.7000, 8.3930, 2.2750, 1.2190, 1.2190, 0.1879]
    center_of_mass = [ [0, -0.02561, 0.00193], [0.2125, 0, 0.11336], [0.11993, 0.0, 0.0265], [0, -0.0018, 0.01634], [0, 0.0018,0.01634], [0, 0, -0.001159] ]
  -->
  <property name="ur5_d1" value="0.089159" />
  <property name="ur5_a2" value="-0.42500" />
  <property name="ur5_a3" value="-0.39225" />
  <property name="ur5_d4" value="0.10915" />
  <property name="ur5_d5" value="0.09465" />
  <property name="ur5_d6" value="0.0823" />

  <!-- Arbitrary offsets for shoulder/elbow joints -->
  <property name="shoulder_offset" value="0.13585" />  <!-- measured from model -->
  <property name="elbow_offset" value="-0.1197" /> <!-- measured from model -->       

  <!-- link lengths used in model -->
  <property name="shoulder_height" value="${ur5_d1}" />
  <property name="upper_arm_length" value="${-ur5_a2}" />
  <property name="forearm_length" value="${-ur5_a3}" />
  <property name="wrist_1_length" value="${ur5_d4 - elbow_offset - shoulder_offset}" />
  <property name="wrist_2_length" value="${ur5_d5}" />
  <property name="wrist_3_length" value="${ur5_d6}" />
  <!--property name="shoulder_height" value="0.089159" /-->  
  <!--property name="shoulder_offset" value="0.13585" /-->  <!-- shoulder_offset - elbow_offset + wrist_1_length = 0.10915 -->
  <!--property name="upper_arm_length" value="0.42500" /-->
  <!--property name="elbow_offset" value="0.1197" /-->       <!-- CAD measured -->
  <!--property name="forearm_length" value="0.39225" /-->
  <!--property name="wrist_1_length" value="0.093" /-->     <!-- CAD measured -->
  <!--property name="wrist_2_length" value="0.09465" /-->   <!-- In CAD this distance is 0.930, but in the spec it is 0.09465 -->
  <!--property name="wrist_3_length" value="0.0823" /-->

    <!-- property list -->
    <xacro:property name="vacuum_gripper_width" value="0.088"/>
    <xacro:property name="arm_prefix" value=""/> 
    <!--<xacro:property name="robot_stand_height" value="0.5"/> -->

  <property name="shoulder_radius" value="0.060" />   <!-- manually measured -->
  <property name="upper_arm_radius" value="0.054" />  <!-- manually measured -->
  <property name="elbow_radius" value="0.060" />      <!-- manually measured -->
  <property name="forearm_radius" value="0.040" />    <!-- manually measured -->
  <property name="wrist_radius" value="0.045" />      <!-- manually measured -->

  <xacro:macro name="cylinder_inertial" params="radius length mass *origin">
    <inertial>
      <mass value="${mass}" />
      <insert_block name="origin" />
      <inertia ixx="${0.0833333 * mass * (3 * radius * radius + length * length)}" ixy="0.0" ixz="0.0"
        iyy="${0.0833333 * mass * (3 * radius * radius + length * length)}" iyz="0.0"
        izz="${0.5 * mass * radius * radius}" />
    </inertial>
  </xacro:macro>

    <!-- instantiating arm and gripper -->
   <xacro:vacuum_gripper_definition prefix="${arm_prefix}" gripper_adjustment="0.01"/> 


  <xacro:macro name="ur5_robot" params="prefix joint_limited">

    <link name="${prefix}base_link" >
      <visual>
        <geometry>
          <mesh filename="package://ur_description/meshes/ur5/visual/base.dae" />
        </geometry>
        <material name="LightGrey">
          <color rgba="0.7 0.7 0.7 1.0"/>
        </material>
      </visual>
      <collision>
        <geometry>
          <mesh filename="package://ur_description/meshes/ur5/collision/base.stl" />
        </geometry>
      </collision>
      <xacro:cylinder_inertial radius="0.06" length="0.05" mass="${base_mass}">
        <origin xyz="0.0 0.0 0.0" rpy="0 0 0" />
      </xacro:cylinder_inertial>
    </link>

    <joint name="${prefix}shoulder_pan_joint" type="revolute">
      <parent link="${prefix}base_link" />
      <child link = "${prefix}shoulder_link" />
      <origin xyz="0.0 0.0 ${shoulder_height}" rpy="0.0 0.0 0.0" />
      <axis xyz="0 0 1" />
      <xacro:unless value="${joint_limited}">
        <limit lower="${-2.0 * pi}" upper="${2.0 * pi}" effort="150.0" velocity="3.15"/>
      </xacro:unless>
      <xacro:if value="${joint_limited}">
        <limit lower="${-pi}" upper="${pi}" effort="150.0" velocity="3.15"/>
      </xacro:if>
      <dynamics damping="0.0" friction="0.0"/>
    </joint>
    
    <link name="${prefix}shoulder_link">
      <visual>
        <geometry>
          <mesh filename="package://ur_description/meshes/ur5/visual/shoulder.dae" />
        </geometry>
        <material name="LightGrey">
          <color rgba="0.7 0.7 0.7 1.0"/>
        </material>
      </visual>
      <collision>
        <geometry>
          <mesh filename="package://ur_description/meshes/ur5/collision/shoulder.stl" />
        </geometry>
      </collision>
      <xacro:cylinder_inertial radius="0.06" length="0.15" mass="${shoulder_mass}">
        <origin xyz="0.0 0.0 0.0" rpy="0 0 0" />
      </xacro:cylinder_inertial>
    </link>

    <joint name="${prefix}shoulder_lift_joint" type="revolute">
      <parent link="${prefix}shoulder_link" />
      <child link = "${prefix}upper_arm_link" />
      <origin xyz="0.0 ${shoulder_offset} 0.0" rpy="0.0 ${pi / 2.0} 0.0" />    
      <axis xyz="0 1 0" />
      <xacro:unless value="${joint_limited}">
        <limit lower="${-2.0 * pi}" upper="${2.0 * pi}" effort="150.0" velocity="3.15"/>
      </xacro:unless>
      <xacro:if value="${joint_limited}">
        <limit lower="${-0.6*pi}" upper="${0.1*pi}" effort="150.0" velocity="3.15"/>
      </xacro:if>
      <dynamics damping="0.0" friction="0.0"/>
    </joint>

    <link name="${prefix}upper_arm_link">
      <visual>
        <geometry>
          <mesh filename="package://ur_description/meshes/ur5/visual/upperarm.dae" />
        </geometry>
        <material name="LightGrey">
          <color rgba="0.7 0.7 0.7 1.0"/>
        </material>
      </visual>
      <collision>
        <geometry>
          <mesh filename="package://ur_description/meshes/ur5/collision/upperarm.stl" />
        </geometry>
      </collision>
      <xacro:cylinder_inertial radius="0.06" length="0.56" mass="${upper_arm_mass}">
        <origin xyz="0.0 0.0 0.28" rpy="0 0 0" />
      </xacro:cylinder_inertial>
    </link>

    <joint name="${prefix}elbow_joint" type="revolute">
      <parent link="${prefix}upper_arm_link" />
      <child link = "${prefix}forearm_link" />
      <origin xyz="0.0 ${elbow_offset} ${upper_arm_length}" rpy="0.0 0.0 0.0" />
      <axis xyz="0 1 0" />
      <xacro:unless value="${joint_limited}">
        <limit lower="${-2.0 * pi}" upper="${2.0 * pi}" effort="150.0" velocity="3.15"/>
      </xacro:unless>
      <xacro:if value="${joint_limited}">
        <limit lower="${-0.08*pi}" upper="${pi}" effort="150.0" velocity="3.15"/>
      </xacro:if>
      <dynamics damping="0.0" friction="0.0"/>
    </joint>

    <link name="${prefix}forearm_link">
      <visual>
        <geometry>
          <mesh filename="package://ur_description/meshes/ur5/visual/forearm.dae" />
        </geometry>
        <material name="LightGrey">
          <color rgba="0.7 0.7 0.7 1.0"/>
        </material>
      </visual>
      <collision>
        <geometry>
          <mesh filename="package://ur_description/meshes/ur5/collision/forearm.stl" />
        </geometry>
      </collision>
      <xacro:cylinder_inertial radius="0.06" length="0.5" mass="${forearm_mass}">
        <origin xyz="0.0 0.0 0.25" rpy="0 0 0" />
      </xacro:cylinder_inertial>
    </link>

    <joint name="${prefix}wrist_1_joint" type="revolute">
      <parent link="${prefix}forearm_link" />
      <child link = "${prefix}wrist_1_link" />
      <origin xyz="0.0 0.0 ${forearm_length}" rpy="0.0 ${pi / 2.0} 0.0" />
      <axis xyz="0 1 0" />
      <xacro:unless value="${joint_limited}">
        <limit lower="${-2.0 * pi}" upper="${2.0 * pi}" effort="28.0" velocity="3.2"/>
      </xacro:unless>
      <xacro:if value="${joint_limited}">
        <limit lower="${-pi}" upper="${pi}" effort="28.0" velocity="3.2"/>
      </xacro:if>
      <dynamics damping="0.0" friction="0.0"/>
    </joint>

    <link name="${prefix}wrist_1_link">
      <visual>
        <geometry>
          <mesh filename="package://ur_description/meshes/ur5/visual/wrist1.dae" />
        </geometry>
        <material name="LightGrey">
          <color rgba="0.7 0.7 0.7 1.0"/>
        </material>
      </visual>
      <collision>
        <geometry>
          <mesh filename="package://ur_description/meshes/ur5/collision/wrist1.stl" />
        </geometry>
      </collision>
      <xacro:cylinder_inertial radius="0.6" length="0.12" mass="${wrist_1_mass}">
        <origin xyz="0.0 0.0 0.0" rpy="0 0 0" />
      </xacro:cylinder_inertial>
    </link>

    <joint name="${prefix}wrist_2_joint" type="revolute">
      <parent link="${prefix}wrist_1_link" />
      <child link = "${prefix}wrist_2_link" />
      <origin xyz="0.0 ${wrist_1_length} 0.0" rpy="0.0 0.0 0.0" />
      <axis xyz="0 0 1" />
      <xacro:unless value="${joint_limited}">
        <limit lower="${-2.0 * pi}" upper="${2.0 * pi}" effort="28.0" velocity="3.2"/>
      </xacro:unless>
      <xacro:if value="${joint_limited}">
        <limit lower="${-pi}" upper="${pi}" effort="28.0" velocity="3.2"/>
      </xacro:if>
      <dynamics damping="0.0" friction="0.0"/>
    </joint>

    <link name="${prefix}wrist_2_link">
      <visual>
        <geometry>
          <mesh filename="package://ur_description/meshes/ur5/visual/wrist2.dae" />
        </geometry>
        <material name="LightGrey">
          <color rgba="0.7 0.7 0.7 1.0"/>
        </material>
      </visual>
      <collision>
        <geometry>
          <mesh filename="package://ur_description/meshes/ur5/collision/wrist2.stl" />
        </geometry>
      </collision>
      <xacro:cylinder_inertial radius="0.6" length="0.12" mass="${wrist_2_mass}">
        <origin xyz="0.0 0.0 0.0" rpy="0 0 0" />
      </xacro:cylinder_inertial>
    </link>

    <joint name="${prefix}wrist_3_joint" type="revolute">
      <parent link="${prefix}wrist_2_link" />
      <child link = "${prefix}wrist_3_link" />
      <origin xyz="0.0 0.0 ${wrist_2_length}" rpy="0.0 0.0 0.0" />
      <axis xyz="0 1 0" />
      <xacro:unless value="${joint_limited}">
        <limit lower="${-2.0 * pi}" upper="${2.0 * pi}" effort="28.0" velocity="3.2"/>
      </xacro:unless>
      <xacro:if value="${joint_limited}">
        <limit lower="${-pi}" upper="${pi}" effort="28.0" velocity="3.2"/>
      </xacro:if>
      <dynamics damping="0.0" friction="0.0"/>
    </joint>

    <link name="${prefix}wrist_3_link">
      <visual>
        <geometry>
          <mesh filename="package://ur_description/meshes/ur5/visual/wrist3.dae" />
        </geometry>
        <material name="LightGrey">
          <color rgba="0.7 0.7 0.7 1.0"/>
        </material>
      </visual>
      <collision>
        <geometry>
          <mesh filename="package://ur_description/meshes/ur5/collision/wrist3.stl" />
        </geometry>
      </collision>
      <xacro:cylinder_inertial radius="0.6" length="0.12" mass="${wrist_3_mass}">
        <origin xyz="0.0 0.0 0.0" rpy="0 0 0" />
      </xacro:cylinder_inertial>
    </link>
    
    <joint name="${prefix}ee_fixed_joint" type="fixed">
      <parent link="${prefix}wrist_3_link" />
      <child link = "${prefix}ee_link" />
      <origin xyz="0.0 ${wrist_3_length} 0.0" rpy="0.0 0.0 ${pi/2.0}" />
    </joint>

    <link name="${prefix}ee_link">
      <collision>
        <geometry>
          <box size="0.01 0.01 0.01"/>
        </geometry>
        <origin rpy="0 0 0" xyz="-0.01 0 0"/>
      </collision>
    </link>
  
    <link name="${prefix}tool_interface_plate">
        <visual>
                <geometry>
                        <box size="0.09525 0.09525 0.0127"/>
                </geometry>
                <material name="orange_transparent"/>
        </visual>
        <collision>
                <geometry>
                        <box size="0.09525 0.09525 0.0127"/>
                </geometry>
                <material name="blue_transparent"/>
        </collision>
    </link> 

   <!-- <link name="ur5_stand">
            <visual>
                    <geometry>
                            <cylinder radius="0.0735" length="${robot_stand_height}"/>
                    </geometry>
            </visual>
            <collision>
                    <geometry>
                            <cylinder radius="0.0735" length="${robot_stand_height}"/>
                    </geometry>
                    <material name="blue_transparent"/>
            </collision>
    </link>  -->

   <!-- <link name="base_padding">
            <collision>
                    <geometry>
                            <cylinder radius="0.14" length="${robot_stand_height}"/>
                    </geometry>
                    <material name="blue_transparent"/>
            </collision>
    </link> -->

   <!-- <joint name="stand_to_base" type="fixed">
            <parent link="ur5_stand"/>
            <child link="base_link"/>
            <origin xyz="0 0 ${robot_stand_height}" rpy="0 0 0"/>
    </joint> -->

  <!--  <joint name="world_to_base_padding" type="fixed">
            <parent link="ur5_stand"/>
            <child link="base_padding"/>
            <origin xyz="-0.238 0 ${robot_stand_height}"/>
    </joint> -->
     <!-- arm-gripper coupling joint definitions -->
   <joint name="${prefix}to_interface_plate" type="fixed">
            <parent link="${prefix}ee_link"/>
            <child link="${prefix}tool_interface_plate"/>
            <origin xyz="0.00635 0 0" rpy="0 1.57  0"/> <!-- 0 1.57 0 -->
    </joint> 

    <!-- arm-gripper coupling joint definitions -->
    <joint name="${prefix}to_gripper" type="fixed">
            <parent link="${prefix}ee_link"/>
            <child link="${prefix}gripper_frame"/>
            <origin xyz="0.02 0 0" rpy="-1.57 0 -1.57"/> <!-- 0 1.57 0 -->
    </joint> 

  <!-- Define arm with gripper mounted on a base -->
  <xacro:base name="base"/>
 <!-- <xacro:arm parent="base"/>
  <xacro:gripper parent="tool"/> -->

  <!-- Define RGB-D sensor -->
  <xacro:xtion_pro_live name="rgbd_camera" parent="base">
    <origin xyz="0.1 0 1" rpy="0 ${75.0 * deg_to_rad} 0"/>
    <origin xyz="0 0 0" rpy="${-90.0 * deg_to_rad} 0 ${-90.0 * deg_to_rad}"/>
</xacro:xtion_pro_live>

    <!-- end of arm-gripper coupling joint definitions -->
    <xacro:ur_arm_transmission prefix="${prefix}" />
    <xacro:ur_arm_gazebo prefix="${prefix}" />

  </xacro:macro>
</robot>

